Traceback (most recent call last):
  File "/opt/hostedtoolcache/Python/3.9.14/x64/lib/python3.9/site-packages/jupyter_cache/executors/utils.py", line 51, in single_nb_execution
    executenb(
  File "/opt/hostedtoolcache/Python/3.9.14/x64/lib/python3.9/site-packages/nbclient/client.py", line 1204, in execute
    return NotebookClient(nb=nb, resources=resources, km=km, **kwargs).execute()
  File "/opt/hostedtoolcache/Python/3.9.14/x64/lib/python3.9/site-packages/nbclient/util.py", line 84, in wrapped
    return just_run(coro(*args, **kwargs))
  File "/opt/hostedtoolcache/Python/3.9.14/x64/lib/python3.9/site-packages/nbclient/util.py", line 62, in just_run
    return loop.run_until_complete(coro)
  File "/opt/hostedtoolcache/Python/3.9.14/x64/lib/python3.9/asyncio/base_events.py", line 647, in run_until_complete
    return future.result()
  File "/opt/hostedtoolcache/Python/3.9.14/x64/lib/python3.9/site-packages/nbclient/client.py", line 663, in async_execute
    await self.async_execute_cell(
  File "/opt/hostedtoolcache/Python/3.9.14/x64/lib/python3.9/site-packages/nbclient/client.py", line 965, in async_execute_cell
    await self._check_raise_for_error(cell, cell_index, exec_reply)
  File "/opt/hostedtoolcache/Python/3.9.14/x64/lib/python3.9/site-packages/nbclient/client.py", line 862, in _check_raise_for_error
    raise CellExecutionError.from_cell_and_msg(cell, exec_reply_content)
nbclient.exceptions.CellExecutionError: An error occurred while executing the following cell:
------------------
layout = BIDSLayout('./ds001734/', database_path="./ds001734.db")
------------------

[0;31m---------------------------------------------------------------------------[0m
[0;31mValueError[0m                                Traceback (most recent call last)
Cell [0;32mIn [2], line 1[0m
[0;32m----> 1[0m layout [38;5;241m=[39m BIDSLayout([38;5;124m'[39m[38;5;124m./ds001734/[39m[38;5;124m'[39m, database_path[38;5;241m=[39m[38;5;124m"[39m[38;5;124m./ds001734.db[39m[38;5;124m"[39m)

File [0;32m~/work/model-zoo/model-zoo/src/pybids/bids/layout/layout.py:127[0m, in [0;36mBIDSLayout.__init__[0;34m(self, root, validate, absolute_paths, derivatives, config, sources, regex_search, database_path, reset_database, indexer, **indexer_kwargs)[0m
[1;32m    124[0m     config [38;5;241m=[39m info[38;5;241m.[39mconfig
[1;32m    126[0m [38;5;66;03m# Validate that a valid BIDS project exists at root[39;00m
[0;32m--> 127[0m root, description [38;5;241m=[39m [43mvalidate_root[49m[43m([49m[43mroot[49m[43m,[49m[43m [49m[43mvalidate[49m[43m)[49m
[1;32m    129[0m [38;5;28mself[39m[38;5;241m.[39m_root [38;5;241m=[39m root  [38;5;66;03m# type: Path[39;00m
[1;32m    130[0m [38;5;28mself[39m[38;5;241m.[39mdescription [38;5;241m=[39m description

File [0;32m~/work/model-zoo/model-zoo/src/pybids/bids/layout/validation.py:73[0m, in [0;36mvalidate_root[0;34m(root, validate)[0m
[1;32m     70[0m root [38;5;241m=[39m root[38;5;241m.[39mabsolute()
[1;32m     72[0m [38;5;28;01mif[39;00m [38;5;129;01mnot[39;00m root[38;5;241m.[39mexists():
[0;32m---> 73[0m     [38;5;28;01mraise[39;00m [38;5;167;01mValueError[39;00m([38;5;124m"[39m[38;5;124mBIDS root does not exist: [39m[38;5;132;01m%s[39;00m[38;5;124m"[39m [38;5;241m%[39m root)
[1;32m     75[0m target [38;5;241m=[39m root [38;5;241m/[39m [38;5;124m'[39m[38;5;124mdataset_description.json[39m[38;5;124m'[39m
[1;32m     76[0m [38;5;28;01mif[39;00m [38;5;129;01mnot[39;00m target[38;5;241m.[39mexists():

[0;31mValueError[0m: BIDS root does not exist: /home/zorro/repos/model-zoo/model-zoo/exhibits/narps/ds001734
ValueError: BIDS root does not exist: /home/zorro/repos/model-zoo/model-zoo/exhibits/narps/ds001734

